[Thu Feb 25 10:02:46 2016] [error] [client 10.255.12.9] mod_wsgi (pid=23535): Exception occurred processing WSGI script '/var/www/html/iggybase/iggybase.wsgi'.
[Thu Feb 25 10:02:46 2016] [error] [client 10.255.12.9] Traceback (most recent call last):
[Thu Feb 25 10:02:46 2016] [error] [client 10.255.12.9]   File "/n/informatics/iggybase/dev/iggybase_env/lib/python3.4/site-packages/flask/app.py", line 1836, in __call__
[Thu Feb 25 10:02:46 2016] [error] [client 10.255.12.9]     return self.wsgi_app(environ, start_response)
[Thu Feb 25 10:02:46 2016] [error] [client 10.255.12.9]   File "/n/informatics/iggybase/dev/iggybase_env/lib/python3.4/site-packages/flask/app.py", line 1820, in wsgi_app
[Thu Feb 25 10:02:46 2016] [error] [client 10.255.12.9]     response = self.make_response(self.handle_exception(e))
[Thu Feb 25 10:02:46 2016] [error] [client 10.255.12.9]   File "/n/informatics/iggybase/dev/iggybase_env/lib/python3.4/site-packages/flask/app.py", line 1403, in handle_exception
[Thu Feb 25 10:02:46 2016] [error] [client 10.255.12.9]     reraise(exc_type, exc_value, tb)
[Thu Feb 25 10:02:46 2016] [error] [client 10.255.12.9]   File "/n/informatics/iggybase/dev/iggybase_env/lib/python3.4/site-packages/flask/_compat.py", line 33, in reraise
[Thu Feb 25 10:02:46 2016] [error] [client 10.255.12.9]     raise value
[Thu Feb 25 10:02:46 2016] [error] [client 10.255.12.9]   File "/n/informatics/iggybase/dev/iggybase_env/lib/python3.4/site-packages/flask/app.py", line 1817, in wsgi_app
[Thu Feb 25 10:02:46 2016] [error] [client 10.255.12.9]     response = self.full_dispatch_request()
[Thu Feb 25 10:02:46 2016] [error] [client 10.255.12.9]   File "/n/informatics/iggybase/dev/iggybase_env/lib/python3.4/site-packages/flask/app.py", line 1477, in full_dispatch_request
[Thu Feb 25 10:02:46 2016] [error] [client 10.255.12.9]     rv = self.handle_user_exception(e)
[Thu Feb 25 10:02:46 2016] [error] [client 10.255.12.9]   File "/n/informatics/iggybase/dev/iggybase_env/lib/python3.4/site-packages/flask/app.py", line 1381, in handle_user_exception
[Thu Feb 25 10:02:46 2016] [error] [client 10.255.12.9]     reraise(exc_type, exc_value, tb)
[Thu Feb 25 10:02:46 2016] [error] [client 10.255.12.9]   File "/n/informatics/iggybase/dev/iggybase_env/lib/python3.4/site-packages/flask/_compat.py", line 33, in reraise
[Thu Feb 25 10:02:46 2016] [error] [client 10.255.12.9]     raise value
[Thu Feb 25 10:02:46 2016] [error] [client 10.255.12.9]   File "/n/informatics/iggybase/dev/iggybase_env/lib/python3.4/site-packages/flask/app.py", line 1475, in full_dispatch_request
[Thu Feb 25 10:02:46 2016] [error] [client 10.255.12.9]     rv = self.dispatch_request()
[Thu Feb 25 10:02:46 2016] [error] [client 10.255.12.9]   File "/n/informatics/iggybase/dev/iggybase_env/lib/python3.4/site-packages/flask/app.py", line 1461, in dispatch_request
[Thu Feb 25 10:02:46 2016] [error] [client 10.255.12.9]     return self.view_functions[rule.endpoint](**req.view_args)
[Thu Feb 25 10:02:46 2016] [error] [client 10.255.12.9]   File "/n/informatics/iggybase/dev/iggybase_env/lib/python3.4/site-packages/flask_login.py", line 792, in decorated_view
[Thu Feb 25 10:02:46 2016] [error] [client 10.255.12.9]     return func(*args, **kwargs)
[Thu Feb 25 10:02:46 2016] [error] [client 10.255.12.9]   File "/n/informatics/iggybase/dev/iggybase/iggybase/mod_core/routes.py", line 212, in data_entry
[Thu Feb 25 10:02:46 2016] [error] [client 10.255.12.9]     return saved_data(module_name, table_name, row_names)
[Thu Feb 25 10:02:46 2016] [error] [client 10.255.12.9]   File "/n/informatics/iggybase/dev/iggybase/iggybase/mod_core/routes.py", line 269, in saved_data
[Thu Feb 25 10:02:46 2016] [error] [client 10.255.12.9]     table = urllib.parse.quote(row_name[1])
[Thu Feb 25 10:02:46 2016] [error] [client 10.255.12.9] NameError: name 'urllib' is not defined
