INFO:root:None
INFO:root:None
INFO:root:None
INFO:root:None
INFO:root:0
INFO:root:0
INFO:root:0
ERROR:sqlalchemy.pool.QueuePool:Exception during reset or similar
Traceback (most recent call last):
  File "/n/informatics/iggybase/iggybase_env/lib/python3.4/site-packages/mysql/connector/network.py", line 226, in recv_plain
    chunk = self.sock.recv(4 - packet_len)
ConnectionResetError: [Errno 104] Connection reset by peer

During handling of the above exception, another exception occurred:

Traceback (most recent call last):
  File "/n/informatics/iggybase/iggybase_env/lib/python3.4/site-packages/sqlalchemy/pool.py", line 631, in _finalize_fairy
    fairy._reset(pool)
  File "/n/informatics/iggybase/iggybase_env/lib/python3.4/site-packages/sqlalchemy/pool.py", line 771, in _reset
    pool._dialect.do_rollback(self)
  File "/n/informatics/iggybase/iggybase_env/lib/python3.4/site-packages/sqlalchemy/dialects/mysql/base.py", line 2519, in do_rollback
    dbapi_connection.rollback()
  File "/n/informatics/iggybase/iggybase_env/lib/python3.4/site-packages/mysql/connector/connection.py", line 1485, in rollback
    self._execute_query("ROLLBACK")
  File "/n/informatics/iggybase/iggybase_env/lib/python3.4/site-packages/mysql/connector/connection.py", line 1499, in _execute_query
    self.cmd_query(query)
  File "/n/informatics/iggybase/iggybase_env/lib/python3.4/site-packages/mysql/connector/connection.py", line 722, in cmd_query
    result = self._handle_result(self._send_cmd(ServerCmd.QUERY, query))
  File "/n/informatics/iggybase/iggybase_env/lib/python3.4/site-packages/mysql/connector/connection.py", line 510, in _send_cmd
    return self._socket.recv()
  File "/n/informatics/iggybase/iggybase_env/lib/python3.4/site-packages/mysql/connector/network.py", line 255, in recv_plain
    errno=2055, values=(self.get_address(), _strioerror(err)))
mysql.connector.errors.OperationalError: 2055: Lost connection to MySQL server at 'db-internal.rc.fas.harvard.edu:3306', system error: 104 Connection reset by peer
